ログを '20250725_222950.log' に保存します。

--- [ステップ1/6] 初回実行中... ---
エラー: スクリプトの実行に失敗しました。
STDOUT:
'Ђv  {s敟PڂPԂSW|QTOR' ɂāAAIvlJn܂...
STDERR:
Traceback (most recent call last):
  File "C:\Users\sinzy\test\py_the_judgment_spiral\gemini_search_app_new_sdk.py", line 167, in <module>
    main()
  File "C:\Users\sinzy\test\py_the_judgment_spiral\gemini_search_app_new_sdk.py", line 100, in main
    fetch_url_tool = types.FunctionDeclaration.from_callable(fetch_url_content)
                     ^^^^^^^^^^^^^^^^^^^^^^^^^^^^^^^^^^^^^^^^^^^^^^^^^^^^^^^^^^
TypeError: FunctionDeclaration.from_callable() takes 1 positional argument but 2 were given

エラー: プロセス全体で予期せぬエラー: gemini_search_app_new_sdk.pyの実行に失敗しました。
Traceback (most recent call last):
  File "C:\Users\sinzy\test\py_the_judgment_spiral\advanced_evaluation_runner_log.py", line 204, in main
    initial_log, _ = await run_search_app(query, key1)
                     ^^^^^^^^^^^^^^^^^^^^^^^^^^^^^^^^^
  File "C:\Users\sinzy\test\py_the_judgment_spiral\advanced_evaluation_runner_log.py", line 52, in run_search_app
    raise RuntimeError("gemini_search_app_new_sdk.pyの実行に失敗しました。")
RuntimeError: gemini_search_app_new_sdk.pyの実行に失敗しました。

