ログを '20250725_223350.log' に保存します。

--- [ステップ1/6] 初回実行中... ---
エラー: スクリプトの実行に失敗しました。
STDOUT:
'株式会社Ｗａｃｈｙ  大阪府大阪市福島区福島１丁目１番４８－２５０３号' について、AIが思考を開始します...
STDERR:
Traceback (most recent call last):
  File "C:\Users\sinzy\test\py_the_judgment_spiral\gemini_search_app_new_sdk.py", line 178, in <module>
    main()
  File "C:\Users\sinzy\test\py_the_judgment_spiral\gemini_search_app_new_sdk.py", line 134, in main
    mode=types.FunctionCallingConfig.Mode.ANY
         ^^^^^^^^^^^^^^^^^^^^^^^^^^^^^^^^
  File "C:\Users\sinzy\AppData\Local\Programs\Python\Python312\Lib\site-packages\pydantic\_internal\_model_construction.py", line 271, in __getattr__
    raise AttributeError(item)
AttributeError: Mode

エラー: プロセス全体で予期せぬエラー: gemini_search_app_new_sdk.pyの実行に失敗しました。
Traceback (most recent call last):
  File "C:\Users\sinzy\test\py_the_judgment_spiral\advanced_evaluation_runner_log.py", line 204, in main
    initial_log, _ = await run_search_app(query, key1)
                     ^^^^^^^^^^^^^^^^^^^^^^^^^^^^^^^^^
  File "C:\Users\sinzy\test\py_the_judgment_spiral\advanced_evaluation_runner_log.py", line 52, in run_search_app
    raise RuntimeError("gemini_search_app_new_sdk.pyの実行に失敗しました。")
RuntimeError: gemini_search_app_new_sdk.pyの実行に失敗しました。

